<!--
  Highland Cow v2 — MuJoCo MJCF Model (RL-optimized)
  ====================================================
  150cm withers-height bovine quadruped for RL locomotion training.

  DESIGN PRINCIPLES (based on state-of-the-art RL locomotion):
  1. PD position actuators — RL outputs target joint angles, PD tracks them
  2. Standing keyframe — cow starts in a valid, stable stance
  3. 12 actuated DOF — 4 legs × 3 joints (hip_roll, hip_pitch, knee)
  4. 2-segment legs — upper + lower with integrated hoof (simplified)
  5. Only feet collide with ground — prevents self-collision chaos
  6. High armature — simulates motor rotor inertia, stabilizes simulation

  Anatomy (scaled Highland Cow):
    Body barrel:  1.10m long × 0.44m wide × 0.44m tall, 80kg
    Head/neck:    decorative, 7kg
    Front legs:   upper 0.45m + lower 0.45m + foot r=0.04m  (3.5+2.5+0.5=6.5kg each)
    Rear legs:    upper 0.48m + lower 0.48m + foot r=0.04m  (4.0+3.0+0.5=7.5kg each)
    Total mass:   ~115 kg

  Standing height:
    Body center at z≈1.00m, withers at ~1.45-1.50m (with hump geometry)
-->
<mujoco model="highland_cow_v2">
  <compiler angle="radian" eulerseq="XYZ" autolimits="true"
            inertiafromgeom="auto"/>

  <option timestep="0.002" iterations="50" solver="Newton"
          gravity="0 0 -9.81" impratio="10">
    <flag warmstart="enable"/>
  </option>

  <!-- ═══ DEFAULTS ═══ -->
  <default>
    <!-- Joints: high armature for stability, moderate damping -->
    <joint armature="0.08" damping="3.0" limited="true"
           solimplimit="0.9 0.95 0.001" solreflimit="0.02 1"/>

    <!-- Geoms: default NO collision (only feet override this) -->
    <geom contype="0" conaffinity="0" condim="3"
          friction="1.0 0.5 0.01" margin="0.001"/>

    <!-- PD actuators: position servo with explicit kp/kd -->
    <general gaintype="fixed" biastype="affine" ctrllimited="true"
             forcelimited="true"/>

    <default class="body_geom">
      <geom rgba="0.55 0.40 0.25 1" type="box"/>
    </default>
    <default class="upper_leg">
      <geom rgba="0.50 0.35 0.20 1" type="capsule"/>
    </default>
    <default class="lower_leg">
      <geom rgba="0.40 0.30 0.18 1" type="capsule"/>
    </default>
    <default class="foot">
      <!-- Feet DO collide with ground -->
      <geom rgba="0.15 0.10 0.05 1" type="sphere"
            contype="1" conaffinity="1" condim="4"
            friction="1.5 0.8 0.02"
            solimp="0.9 0.95 0.001" solref="0.01 1"/>
    </default>
  </default>

  <asset>
    <texture type="skybox" builtin="gradient" rgb1="0.6 0.7 0.9" rgb2="0.2 0.3 0.5"
             width="512" height="512"/>
    <texture name="grid" type="2d" builtin="checker" rgb1="0.4 0.5 0.3"
             rgb2="0.3 0.4 0.2" width="512" height="512"/>
    <material name="grid" texture="grid" texrepeat="8 8" reflectance="0.1"/>
  </asset>

  <worldbody>
    <!-- Ground plane — collides with feet only -->
    <geom name="floor" type="plane" size="50 50 0.1" material="grid"
          contype="1" conaffinity="1" condim="4"
          friction="1.0 0.5 0.01"/>

    <!-- ═══ HIGHLAND COW BODY ═══ -->
    <body name="torso" pos="0 0 1.02">
      <freejoint name="root"/>

      <!-- IMU sensor site at body center -->
      <site name="imu_site" pos="0 0 0" size="0.01"/>

      <!-- Main barrel — 80 kg -->
      <inertial pos="0 0 0" mass="80.0"
                diaginertia="3.5 10.0 10.5"/>
      <geom class="body_geom" name="barrel" pos="0 0 0"
            size="0.55 0.22 0.22"/>
      <!-- Withers hump -->
      <geom class="body_geom" name="withers" pos="0.30 0 0.28"
            size="0.20 0.20 0.08"/>
      <!-- Rump rise -->
      <geom class="body_geom" name="rump" pos="-0.35 0 0.25"
            size="0.15 0.19 0.05"/>

      <!-- ── HEAD (decorative, 7 kg) ── -->
      <body name="head" pos="0.60 0 0.15">
        <inertial pos="0.15 0 0.10" mass="7.0"
                  diaginertia="0.08 0.10 0.06"/>
        <geom name="neck" type="capsule" fromto="0 0 0 0.12 0 0.20"
              size="0.07" rgba="0.55 0.40 0.25 1"/>
        <geom name="skull" type="ellipsoid" pos="0.20 0 0.28"
              size="0.16 0.10 0.12" rgba="0.55 0.40 0.25 1"/>
      </body>

      <!-- ═══════════════════════════════════════
           FRONT-LEFT LEG
           hip_roll(X) → hip_pitch(Y) → knee(Y) → foot
           Hip at front-left of body
      ═══════════════════════════════════════ -->
      <body name="fl_hip" pos="0.35 0.18 -0.12">
        <joint name="fl_hip_roll" type="hinge" axis="1 0 0"
               range="-0.4 0.4" damping="3.0" armature="0.05"/>
        <joint name="fl_hip_pitch" type="hinge" axis="0 1 0"
               range="-0.8 0.8" damping="5.0" armature="0.08"/>
        <inertial pos="0 0 -0.225" mass="3.5"
                  diaginertia="0.060 0.060 0.004"/>
        <geom class="upper_leg" fromto="0 0 0 0 0 -0.45"
              size="0.04" name="fl_upper_geom"/>

        <body name="fl_lower" pos="0 0 -0.45">
          <joint name="fl_knee" type="hinge" axis="0 1 0"
                 range="-1.6 -0.1" damping="5.0" armature="0.08"/>
          <inertial pos="0 0 -0.225" mass="2.5"
                    diaginertia="0.042 0.042 0.002"/>
          <geom class="lower_leg" fromto="0 0 0 0 0 -0.45"
                size="0.035" name="fl_lower_geom"/>

          <!-- Hoof -->
          <body name="fl_foot" pos="0 0 -0.45">
            <geom class="foot" name="fl_foot_geom" size="0.04" mass="0.5"/>
            <site name="fl_foot_site" pos="0 0 -0.04" size="0.01"/>
          </body>
        </body>
      </body>

      <!-- ═══════════════════════════════════════
           FRONT-RIGHT LEG
      ═══════════════════════════════════════ -->
      <body name="fr_hip" pos="0.35 -0.18 -0.12">
        <joint name="fr_hip_roll" type="hinge" axis="1 0 0"
               range="-0.4 0.4" damping="3.0" armature="0.05"/>
        <joint name="fr_hip_pitch" type="hinge" axis="0 1 0"
               range="-0.8 0.8" damping="5.0" armature="0.08"/>
        <inertial pos="0 0 -0.225" mass="3.5"
                  diaginertia="0.060 0.060 0.004"/>
        <geom class="upper_leg" fromto="0 0 0 0 0 -0.45"
              size="0.04" name="fr_upper_geom"/>

        <body name="fr_lower" pos="0 0 -0.45">
          <joint name="fr_knee" type="hinge" axis="0 1 0"
                 range="-1.6 -0.1" damping="5.0" armature="0.08"/>
          <inertial pos="0 0 -0.225" mass="2.5"
                    diaginertia="0.042 0.042 0.002"/>
          <geom class="lower_leg" fromto="0 0 0 0 0 -0.45"
                size="0.035" name="fr_lower_geom"/>

          <body name="fr_foot" pos="0 0 -0.45">
            <geom class="foot" name="fr_foot_geom" size="0.04" mass="0.5"/>
            <site name="fr_foot_site" pos="0 0 -0.04" size="0.01"/>
          </body>
        </body>
      </body>

      <!-- ═══════════════════════════════════════
           REAR-LEFT LEG (longer segments, cow anatomy)
      ═══════════════════════════════════════ -->
      <body name="rl_hip" pos="-0.35 0.18 -0.08">
        <joint name="rl_hip_roll" type="hinge" axis="1 0 0"
               range="-0.4 0.4" damping="3.0" armature="0.05"/>
        <joint name="rl_hip_pitch" type="hinge" axis="0 1 0"
               range="-0.8 0.8" damping="5.0" armature="0.08"/>
        <inertial pos="0 0 -0.24" mass="4.0"
                  diaginertia="0.077 0.077 0.005"/>
        <geom class="upper_leg" fromto="0 0 0 0 0 -0.48"
              size="0.045" name="rl_upper_geom"/>

        <body name="rl_lower" pos="0 0 -0.48">
          <joint name="rl_knee" type="hinge" axis="0 1 0"
                 range="-1.6 -0.1" damping="5.0" armature="0.08"/>
          <inertial pos="0 0 -0.24" mass="3.0"
                    diaginertia="0.058 0.058 0.003"/>
          <geom class="lower_leg" fromto="0 0 0 0 0 -0.48"
                size="0.04" name="rl_lower_geom"/>

          <body name="rl_foot" pos="0 0 -0.48">
            <geom class="foot" name="rl_foot_geom" size="0.04" mass="0.5"/>
            <site name="rl_foot_site" pos="0 0 -0.04" size="0.01"/>
          </body>
        </body>
      </body>

      <!-- ═══════════════════════════════════════
           REAR-RIGHT LEG
      ═══════════════════════════════════════ -->
      <body name="rr_hip" pos="-0.35 -0.18 -0.08">
        <joint name="rr_hip_roll" type="hinge" axis="1 0 0"
               range="-0.4 0.4" damping="3.0" armature="0.05"/>
        <joint name="rr_hip_pitch" type="hinge" axis="0 1 0"
               range="-0.8 0.8" damping="5.0" armature="0.08"/>
        <inertial pos="0 0 -0.24" mass="4.0"
                  diaginertia="0.077 0.077 0.005"/>
        <geom class="upper_leg" fromto="0 0 0 0 0 -0.48"
              size="0.045" name="rr_upper_geom"/>

        <body name="rr_lower" pos="0 0 -0.48">
          <joint name="rr_knee" type="hinge" axis="0 1 0"
                 range="-1.6 -0.1" damping="5.0" armature="0.08"/>
          <inertial pos="0 0 -0.24" mass="3.0"
                    diaginertia="0.058 0.058 0.003"/>
          <geom class="lower_leg" fromto="0 0 0 0 0 -0.48"
                size="0.04" name="rr_lower_geom"/>

          <body name="rr_foot" pos="0 0 -0.48">
            <geom class="foot" name="rr_foot_geom" size="0.04" mass="0.5"/>
            <site name="rr_foot_site" pos="0 0 -0.04" size="0.01"/>
          </body>
        </body>
      </body>

    </body> <!-- /torso -->
  </worldbody>

  <!-- ═══════════════════════════════════════════════════════
       ACTUATORS — PD Position Servos (12 DOF)
       force = kp * (ctrl - qpos) - kd * qvel
       ctrl = target joint position (set by RL policy)
       kp/kd scaled for ~115 kg quadruped
  ═══════════════════════════════════════════════════════ -->
  <actuator>
    <!-- FRONT-LEFT: hip_roll, hip_pitch, knee -->
    <general name="fl_hip_roll_act"  joint="fl_hip_roll"
             gainprm="80 0 0"  biasprm="0 -80 -4"   biastype="affine"
             ctrlrange="-0.4 0.4"   forcerange="-120 120"/>
    <general name="fl_hip_pitch_act" joint="fl_hip_pitch"
             gainprm="200 0 0" biasprm="0 -200 -10"  biastype="affine"
             ctrlrange="-0.8 0.8"   forcerange="-350 350"/>
    <general name="fl_knee_act"      joint="fl_knee"
             gainprm="200 0 0" biasprm="0 -200 -10"  biastype="affine"
             ctrlrange="-1.6 -0.1"  forcerange="-400 400"/>

    <!-- FRONT-RIGHT -->
    <general name="fr_hip_roll_act"  joint="fr_hip_roll"
             gainprm="80 0 0"  biasprm="0 -80 -4"   biastype="affine"
             ctrlrange="-0.4 0.4"   forcerange="-120 120"/>
    <general name="fr_hip_pitch_act" joint="fr_hip_pitch"
             gainprm="200 0 0" biasprm="0 -200 -10"  biastype="affine"
             ctrlrange="-0.8 0.8"   forcerange="-350 350"/>
    <general name="fr_knee_act"      joint="fr_knee"
             gainprm="200 0 0" biasprm="0 -200 -10"  biastype="affine"
             ctrlrange="-1.6 -0.1"  forcerange="-400 400"/>

    <!-- REAR-LEFT -->
    <general name="rl_hip_roll_act"  joint="rl_hip_roll"
             gainprm="80 0 0"  biasprm="0 -80 -4"   biastype="affine"
             ctrlrange="-0.4 0.4"   forcerange="-120 120"/>
    <general name="rl_hip_pitch_act" joint="rl_hip_pitch"
             gainprm="200 0 0" biasprm="0 -200 -10"  biastype="affine"
             ctrlrange="-0.8 0.8"   forcerange="-350 350"/>
    <general name="rl_knee_act"      joint="rl_knee"
             gainprm="200 0 0" biasprm="0 -200 -10"  biastype="affine"
             ctrlrange="-1.6 -0.1"  forcerange="-400 400"/>

    <!-- REAR-RIGHT -->
    <general name="rr_hip_roll_act"  joint="rr_hip_roll"
             gainprm="80 0 0"  biasprm="0 -80 -4"   biastype="affine"
             ctrlrange="-0.4 0.4"   forcerange="-120 120"/>
    <general name="rr_hip_pitch_act" joint="rr_hip_pitch"
             gainprm="200 0 0" biasprm="0 -200 -10"  biastype="affine"
             ctrlrange="-0.8 0.8"   forcerange="-350 350"/>
    <general name="rr_knee_act"      joint="rr_knee"
             gainprm="200 0 0" biasprm="0 -200 -10"  biastype="affine"
             ctrlrange="-1.6 -0.1"  forcerange="-400 400"/>
  </actuator>

  <!-- ═══════════════════════════════════════════════════════
       SENSORS
  ═══════════════════════════════════════════════════════ -->
  <sensor>
    <accelerometer name="imu_acc" site="imu_site"/>
    <gyro name="imu_gyro" site="imu_site"/>
    <framequat name="body_quat" objtype="site" objname="imu_site"/>
    <framelinvel name="body_linvel" objtype="site" objname="imu_site"/>
    <frameangvel name="body_angvel" objtype="site" objname="imu_site"/>

    <touch name="fl_foot_touch" site="fl_foot_site"/>
    <touch name="fr_foot_touch" site="fr_foot_site"/>
    <touch name="rl_foot_touch" site="rl_foot_site"/>
    <touch name="rr_foot_touch" site="rr_foot_site"/>
  </sensor>

  <!-- ═══════════════════════════════════════════════════════
       KEYFRAME — Natural standing pose
       qpos order: freejoint(7) + 12 hinge joints
       freejoint: x y z  qw qx qy qz
       joints (per leg): hip_roll hip_pitch knee
       Standing angles computed so feet touch ground at z≈0

       Front legs: roll=0.05, pitch=0.0, knee=-0.55
         effective height = 0.45*cos(0) + 0.45*cos(-0.55) + 0.04
                         = 0.45 + 0.45*0.852 + 0.04 = 0.874m
         hip at z=1.02-0.12=0.90 → foot at 0.90-0.874=0.026 ✓

       Rear legs: roll=0.05, pitch=-0.10, knee=-0.60
         effective height = 0.48*cos(-0.10) + 0.48*cos(-0.70) + 0.04
                         = 0.48*0.995 + 0.48*0.765 + 0.04 = 0.885m
         hip at z=1.02-0.08=0.94 → foot at 0.94-0.885=0.055 ✓
  ═══════════════════════════════════════════════════════ -->
  <keyframe>
    <key name="standing" qpos="
      0 0 1.02  1 0 0 0
      0.05  0.0  -0.55
     -0.05  0.0  -0.55
      0.05 -0.10 -0.60
     -0.05 -0.10 -0.60
    " ctrl="
      0.05  0.0  -0.55
     -0.05  0.0  -0.55
      0.05 -0.10 -0.60
     -0.05 -0.10 -0.60
    "/>
  </keyframe>
</mujoco>
